Workbook

Sheet Dataset
A1: 1.Delay in delivering material to construction site | B1: ID | C1: 1.Delay in delivering material to construction site | D1: 2.Monopoly of material by some suppliers | E1: 3.Prices fluctuation | F1: 4.Types of material availability at local market | G1: 5.Lack of consultant’s knowledge of available materials | H1: 6.Low productivity | I1: 7.Poor work execution | J1: 8.Shortage of laborers | K1: 9.Mistakes happens during construction phase | L1: 10.Unavailability of equipment | M1: 11.Lack of engineering experience | N1: 12.Construction cost underestimation | O1: 13.Poor site management | P1: 14.Delayed payment for completed work | Q1: 15.Cash flow problem during construction | R1: 16.High rate of interest | S1: 17.Contractor’s financial difficulties | T1: 18.Increase in salaries of skilled laborers | U1: 19.Change design | V1: 20.Errors and omission in design | W1: 21.Incomplete design drawings and specifications at tendering stage | X1: 22.Delay in preparation and approval of drawing | Y1: 23.Inaccurate quantity take-off | Z1: 24.Long period from planning of project to construction | AA1: 25.Delays in issuing information to the contractor during construction stage | AB1: 26.No practical use of earned value management system | AC1: 27.Lack of cost planning/monitoring during pre and post contract stage | AD1: 28.Poor communication between client, consultant and contractor | AE1: 29.Insufficient coordination between local authority who is responsible about road projects and service authorities | AF1: 30.Delays in decisions making by the approval authorities | AG1: 31.Change schedule | AH1: 32.Stoppages because of work being rejected by consultant | AI1: 33.Lowest bid price | AJ1: 34.Insufficient time for preparation of contract documents | AK1: 35.Discrepancies in contract documents | AL1: 36.Underestimation of time for completion of project | AM1: 37.Extension of time with cost claims | AN1: 38.Scope and specification changes | AO1: 39.Changes in client requirements | AP1: 40.Frequency of variation orders and additional works | AQ1: 41.Rework due to error in execution | AR1: 42.Weather conditions | AS1: 43.Accidents during construction | AT1: 44.Delay in getting NOCs from different government authorities | AU1: Type of Organization | AV1: Respondents designation | AW1: Indicate the highest formal qualification | AX1: How often do you experience cost overrun | AY1: Location of organization | AZ1: Relevant working experience
A2: 2.Monopoly of material by some suppliers | B2: ID001 | C2: 1 | D2: 1 | E2: 1 | F2: 1 | G2: 1 | H2: 1 | I2: 1 | J2: 1 | K2: 1 | L2: 1 | M2: 1 | N2: 1 | O2: 1 | P2: 1 | Q2: 1 | R2: 1 | S2: 1 | T2: 1 | U2: 3 | V2: 3 | W2: 3 | X2: 4 | Y2: 4 | Z2: 3 | AA2: 3 | AB2: 2 | AC2: 1 | AD2: 2 | AE2: 4 | AF2: 4 | AG2: 1 | AH2: 1 | AI2: 2 | AJ2: 2 | AK2: 2 | AL2: 2 | AM2: 2 | AN2: 3 | AO2: 3 | AP2: 3 | AQ2: 1 | AR2: 2 | AS2: 2 | AT2: 3 | AU2: 1 | AV2: 2 | AW2: 2 | AX2: 2 | AY2: 3 | AZ2: 5
A3: 3.Prices fluctuation | B3: ID002 | C3: 2 | D3: 5 | E3: 3 | F3: 2 | G3: 3 | H3: 2 | I3: 2 | J3: 2 | K3: 3 | L3: 2 | M3: 2 | N3: 2 | O3: 2 | P3: 2 | Q3: 2 | R3: 1 | S3: 4 | T3: 1 | U3: 5 | V3: 5 | W3: 4 | X3: 4 | Y3: 4 | Z3: 5 | AA3: 3 | AB3: 3 | AC3: 3 | AD3: 4 | AE3: 4 | AF3: 3 | AG3: 4 | AH3: 4 | AI3: 5 | AJ3: 3 | AK3: 4 | AL3: 4 | AM3: 4 | AN3: 3 | AO3: 3 | AP3: 4 | AQ3: 3 | AR3: 1 | AS3: 1 | AT3: 4 | AU3: 1 | AV3: 3 | AW3: 2 | AX3: 3 | AY3: 3 | AZ3: 3
A4: 4.Types of material availability at local market | B4: ID003 | C4: 1 | D4: 2 | E4: 1 | F4: 1 | G4: 2 | H4: 2 | I4: 1 | J4: 2 | K4: 1 | L4: 1 | M4: 2 | N4: 1 | O4: 3 | P4: 3 | Q4: 3 | R4: 2 | S4: 2 | T4: 1 | U4: 2 | V4: 2 | W4: 2 | X4: 2 | Y4: 3 | Z4: 2 | AA4: 3 | AB4: 1 | AC4: 2 | AD4: 1 | AE4: 3 | AF4: 4 | AG4: 3 | AH4: 1 | AI4: 2 | AJ4: 2 | AK4: 2 | AL4: 2 | AM4: 4 | AN4: 2 | AO4: 2 | AP4: 2 | AQ4: 2 | AR4: 1 | AS4: 1 | AT4: 4 | AU4: 1 | AV4: 2 | AW4: 2 | AX4: 1 | AY4: 2 | AZ4: 4
A5: 5.Lack of consultant’s knowledge of available materials | B5: ID004 | C5: 2 | D5: 2 | E5: 3 | F5: 3 | G5: 2 | H5: 2 | I5: 3 | J5: 4 | K5: 4 | L5: 4 | M5: 2 | N5: 5 | O5: 2 | P5: 2 | Q5: 1 | R5: 1 | S5: 1 | T5: 1 | U5: 4 | V5: 4 | W5: 4 | X5: 4 | Y5: 4 | Z5: 3 | AA5: 2 | AB5: 2 | AC5: 2 | AD5: 2 | AE5: 3 | AF5: 3 | AG5: 2 | AH5: 2 | AI5: 2 | AJ5: 3 | AK5: 2 | AL5: 4 | AM5: 4 | AN5: 4 | AO5: 4 | AP5: 4 | AQ5: 3 | AR5: 4 | AS5: 3 | AT5: 3 | AU5: 1 | AV5: 3 | AW5: 1 | AX5: 1 | AY5: 3 | AZ5: 4
A6: 6.Low productivity | B6: ID005 | C6: 1 | D6: 2 | E6: 1 | F6: 1 | G6: 2 | H6: 2 | I6: 1 | J6: 2 | K6: 1 | L6: 1 | M6: 2 | N6: 1 | O6: 2 | P6: 4 | Q6: 4 | R6: 2 | S6: 2 | T6: 1 | U6: 2 | V6: 2 | W6: 2 | X6: 2 | Y6: 3 | Z6: 2 | AA6: 4 | AB6: 3 | AC6: 2 | AD6: 1 | AE6: 3 | AF6: 4 | AG6: 3 | AH6: 1 | AI6: 2 | AJ6: 2 | AK6: 2 | AL6: 2 | AM6: 4 | AN6: 2 | AO6: 2 | AP6: 2 | AQ6: 2 | AR6: 1 | AS6: 1 | AT6: 4 | AU6: 1 | AV6: 2 | AW6: 3 | AX6: 1 | AY6: 2 | AZ6: 4
A7: 7.Poor work execution | B7: ID006 | C7: 1 | D7: 1 | E7: 1 | F7: 1 | G7: 1 | H7: 2 | I7: 2 | J7: 2 | K7: 1 | L7: 1 | M7: 1 | N7: 2 | O7: 1 | P7: 4 | Q7: 4 | R7: 4 | S7: 4 | T7: 1 | U7: 4 | V7: 4 | W7: 4 | X7: 4 | Y7: 4 | Z7: 4 | AA7: 2 | AB7: 2 | AC7: 2 | AD7: 1 | AE7: 1 | AF7: 3 | AG7: 3 | AH7: 4 | AI7: 2 | AJ7: 2 | AK7: 2 | AL7: 2 | AM7: 2 | AN7: 3 | AO7: 2 | AP7: 3 | AQ7: 3 | AR7: 2 | AS7: 2 | AT7: 2 | AU7: 1 | AV7: 4 | AW7: 2 | AX7: 1 | AY7: 3 | AZ7: 5
A8: 8.Shortage of laborers | B8: ID007 | C8: 1 | D8: 1 | E8: 1 | F8: 1 | G8: 1 | H8: 1 | I8: 1 | J8: 1 | K8: 1 | L8: 1 | M8: 1 | N8: 1 | O8: 1 | P8: 4 | Q8: 4 | R8: 4 | S8: 4 | T8: 1 | U8: 4 | V8: 4 | W8: 4 | X8: 4 | Y8: 4 | Z8: 4 | AA8: 2 | AB8: 2 | AC8: 2 | AD8: 1 | AE8: 2 | AF8: 4 | AG8: 3 | AH8: 4 | AI8: 2 | AJ8: 2 | AK8: 2 | AL8: 2 | AM8: 4 | AN8: 4 | AO8: 3 | AP8: 4 | AQ8: 4 | AR8: 2 | AS8: 2 | AT8: 2 | AU8: 1 | AV8: 5 | AW8: 2 | AX8: 1 | AY8: 3 | AZ8: 5
A9: 9.Mistakes happens during construction phase | B9: ID008 | C9: 1 | D9: 1 | E9: 1 | F9: 1 | G9: 1 | H9: 1 | I9: 1 | J9: 1 | K9: 1 | L9: 1 | M9: 1 | N9: 1 | O9: 1 | P9: 3 | Q9: 3 | R9: 3 | S9: 4 | T9: 4 | U9: 4 | V9: 4 | W9: 4 | X9: 4 | Y9: 4 | Z9: 4 | AA9: 2 | AB9: 2 | AC9: 2 | AD9: 1 | AE9: 1 | AF9: 3 | AG9: 3 | AH9: 4 | AI9: 2 | AJ9: 2 | AK9: 2 | AL9: 2 | AM9: 2 | AN9: 3 | AO9: 2 | AP9: 3 | AQ9: 3 | AR9: 2 | AS9: 2 | AT9: 2 | AU9: 1 | AV9: 4 | AW9: 2 | AX9: 1 | AY9: 3 | AZ9: 5
A10: 10.Unavailability of equipment | B10: ID009 | C10: 1 | D10: 1 | E10: 1 | F10: 1 | G10: 1 | H10: 1 | I10: 1 | J10: 1 | K10: 1 | L10: 1 | M10: 1 | N10: 1 | O10: 1 | P10: 4 | Q10: 4 | R10: 4 | S10: 4 | T10: 3 | U10: 4 | V10: 4 | W10: 4 | X10: 4 | Y10: 4 | Z10: 4 | AA10: 2 | AB10: 2 | AC10: 2 | AD10: 1 | AE10: 2 | AF10: 4 | AG10: 3 | AH10: 4 | AI10: 2 | AJ10: 2 | AK10: 2 | AL10: 2 | AM10: 2 | AN10: 4 | AO10: 3 | AP10: 4 | AQ10: 4 | AR10: 2 | AS10: 2 | AT10: 2 | AU10: 1 | AV10: 4 | AW10: 2 | AX10: 1 | AY10: 3 | AZ10: 5
A11: 11.Lack of engineering experience | B11: ID010 | C11: 1 | D11: 1 | E11: 1 | F11: 1 | G11: 1 | H11: 1 | I11: 1 | J11: 1 | K11: 1 | L11: 1 | M11: 1 | N11: 1 | O11: 1 | P11: 4 | Q11: 4 | R11: 4 | S11: 4 | T11: 2 | U11: 4 | V11: 4 | W11: 4 | X11: 4 | Y11: 4 | Z11: 4 | AA11: 2 | AB11: 2 | AC11: 2 | AD11: 1 | AE11: 1 | AF11: 3 | AG11: 3 | AH11: 4 | AI11: 2 | AJ11: 2 | AK11: 2 | AL11: 2 | AM11: 2 | AN11: 3 | AO11: 2 | AP11: 3 | AQ11: 3 | AR11: 2 | AS11: 2 | AT11: 2 | AU11: 1 | AV11: 4 | AW11: 2 | AX11: 1 | AY11: 3 | AZ11: 5
A12: 12.Construction cost underestimation | B12: ID011 | C12: 2 | D12: 4 | E12: 4 | F12: 1 | G12: 1 | H12: 5 | I12: 1 | J12: 4 | K12: 5 | L12: 3 | M12: 2 | N12: 5 | O12: 2 | P12: 1 | Q12: 1 | R12: 1 | S12: 1 | T12: 3 | U12: 5 | V12: 2 | W12: 3 | X12: 4 | Y12: 3 | Z12: 2 | AA12: 2 | AB12: 1 | AC12: 2 | AD12: 1 | AE12: 5 | AF12: 1 | AG12: 1 | AH12: 1 | AI12: 1 | AJ12: 1 | AK12: 1 | AL12: 3 | AM12: 3 | AN12: 4 | AO12: 4 | AP12: 4 | AQ12: 1 | AR12: 1 | AS12: 1 | AT12: 1 | AU12: 1 | AV12: 5 | AW12: 3 | AX12: 2 | AY12: 3 | AZ12: 4
A13: 13.Poor site management | B13: ID012 | C13: 2 | D13: 1 | E13: 3 | F13: 4 | G13: 4 | H13: 3 | I13: 3 | J13: 4 | K13: 3 | L13: 4 | M13: 5 | N13: 4 | O13: 3 | P13: 3 | Q13: 4 | R13: 2 | S13: 4 | T13: 2 | U13: 4 | V13: 4 | W13: 5 | X13: 3 | Y13: 4 | Z13: 3 | AA13: 3 | AB13: 3 | AC13: 3 | AD13: 4 | AE13: 4 | AF13: 4 | AG13: 3 | AH13: 4 | AI13: 4 | AJ13: 3 | AK13: 3 | AL13: 4 | AM13: 4 | AN13: 4 | AO13: 4 | AP13: 4 | AQ13: 4 | AR13: 2 | AS13: 2 | AT13: 3 | AU13: 1 | AV13: 2 | AW13: 2 | AX13: 1 | AY13: 3 | AZ13: 5
... A44: 44.Delay in getting NOCs from different government authorities | B44: ID043 | C44: 4 | D44: 5 | E44: 3 | F44: 4 | G44: 4 | H44: 4 | I44: 5 | J44: 4 | K44: 4 | L44: 4 | M44: 4 | N44: 4 | O44: 4 | P44: 5 | Q44: 5 | R44: 5 | S44: 4 | T44: 3 | U44: 5 | V44: 4 | W44: 4 | X44: 4 | Y44: 4 | Z44: 3 | AA44: 4 | AB44: 3 | AC44: 4 | AD44: 4 | AE44: 4 | AF44: 4 | AG44: 4 | AH44: 4 | AI44: 1 | AJ44: 2 | AK44: 3 | AL44: 4 | AM44: 5 | AN44: 4 | AO44: 5 | AP44: 4 | AQ44: 4 | AR44: 3 | AS44: 3 | AT44: 5 | AU44: 1 | AV44: 3 | AW44: 3 | AX44: 1 | AY44: 2 | AZ44: 4
A45: Type of Organization | B45: ID044 | C45: 4 | D45: 5 | E45: 3 | F45: 4 | G45: 4 | H45: 4 | I45: 5 | J45: 4 | K45: 4 | L45: 5 | M45: 4 | N45: 4 | O45: 4 | P45: 5 | Q45: 5 | R45: 5 | S45: 4 | T45: 3 | U45: 5 | V45: 4 | W45: 4 | X45: 4 | Y45: 4 | Z45: 3 | AA45: 4 | AB45: 3 | AC45: 4 | AD45: 3 | AE45: 3 | AF45: 4 | AG45: 4 | AH45: 4 | AJ45: 5 | AK45: 4 | AL45: 3 | AM45: 4 | AN45: 5 | AO45: 4 | AP45: 5 | AQ45: 3 | AR45: 2 | AS45: 2 | AT45: 5 | AU45: 1 | AV45: 3 | AW45: 2 | AX45: 1 | AY45: 1 | AZ45: 4
A46: Respondents designation | B46: ID045 | C46: 4 | D46: 5 | E46: 3 | F46: 4 | G46: 4 | H46: 4 | I46: 5 | J46: 4 | K46: 4 | L46: 5 | M46: 4 | N46: 4 | O46: 4 | P46: 5 | Q46: 5 | R46: 5 | S46: 4 | T46: 3 | U46: 5 | V46: 4 | W46: 4 | X46: 4 | Y46: 4 | Z46: 3 | AA46: 4 | AB46: 3 | AC46: 4 | AD46: 3 | AE46: 3 | AF46: 4 | AG46: 4 | AH46: 4 | AI46: 5 | AJ46: 4 | AK46: 3 | AL46: 4 | AM46: 5 | AN46: 4 | AO46: 5 | AP46: 4 | AQ46: 4 | AR46: 3 | AS46: 3 | AT46: 5 | AU46: 2 | AV46: 3 | AW46: 3 | AX46: 1 | AY46: 1 | AZ46: 4
A47: Indicate the highest formal qualification | B47: ID046 | C47: 4 | D47: 5 | E47: 3 | F47: 4 | G47: 4 | H47: 4 | I47: 5 | J47: 4 | K47: 4 | L47: 5 | M47: 4 | N47: 4 | O47: 4 | P47: 5 | Q47: 5 | R47: 5 | S47: 4 | T47: 3 | U47: 5 | V47: 4 | W47: 4 | X47: 4 | Y47: 4 | Z47: 3 | AA47: 4 | AB47: 3 | AC47: 4 | AD47: 4 | AE47: 4 | AF47: 5 | AG47: 4 | AH47: 4 | AI47: 5 | AJ47: 4 | AK47: 3 | AL47: 4 | AM47: 5 | AN47: 4 | AO47: 5 | AP47: 4 | AQ47: 4 | AR47: 3 | AS47: 3 | AT47: 5 | AU47: 2 | AV47: 2 | AW47: 3 | AX47: 1 | AY47: 3 | AZ47: 4
A48: How often do you experience cost overrun | B48: ID047 | C48: 4 | D48: 3 | E48: 3 | F48: 3 | G48: 3 | H48: 5 | I48: 5 | J48: 5 | K48: 5 | L48: 5 | M48: 4 | N48: 4 | O48: 4 | P48: 4 | Q48: 4 | R48: 3 | S48: 3 | T48: 3 | U48: 3 | V48: 2 | W48: 2 | X48: 4 | Y48: 3 | Z48: 2 | AA48: 3 | AB48: 4 | AC48: 4 | AD48: 5 | AE48: 5 | AF48: 5 | AG48: 4 | AH48: 4 | AI48: 3 | AJ48: 4 | AK48: 4 | AL48: 5 | AM48: 4 | AN48: 5 | AO48: 3 | AP48: 3 | AQ48: 4 | AR48: 3 | AS48: 2 | AT48: 4 | AU48: 2 | AV48: 2 | AW48: 2 | AX48: 2 | AY48: 3 | AZ48: 4
A49: Location of organization | B49: ID048 | C49: 1 | D49: 1 | E49: 2 | F49: 2 | G49: 2 | H49: 4 | I49: 4 | J49: 3 | K49: 4 | L49: 4 | M49: 5 | N49: 5 | O49: 5 | P49: 5 | Q49: 5 | R49: 5 | S49: 4 | T49: 3 | U49: 3 | V49: 4 | W49: 3 | X49: 4 | Y49: 4 | Z49: 4 | AA49: 3 | AB49: 2 | AC49: 4 | AD49: 5 | AE49: 5 | AF49: 5 | AG49: 3 | AH49: 2 | AI49: 4 | AJ49: 5 | AK49: 5 | AL49: 4 | AM49: 5 | AN49: 5 | AO49: 5 | AP49: 4 | AQ49: 5 | AR49: 3 | AS49: 5 | AT49: 4 | AU49: 2 | AV49: 5 | AW49: 2 | AX49: 1 | AY49: 1 | AZ49: 5
A50: Relevant working experience | B50: ID049 | C50: 4 | D50: 2 | E50: 4 | F50: 4 | G50: 3 | H50: 4 | I50: 5 | J50: 3 | K50: 5 | L50: 3 | M50: 5 | N50: 5 | O50: 5 | P50: 4 | Q50: 4 | R50: 3 | S50: 2 | T50: 2 | U50: 4 | V50: 5 | W50: 4 | X50: 4 | Y50: 4 | Z50: 4 | AA50: 3 | AB50: 3 | AC50: 4 | AD50: 4 | AE50: 5 | AF50: 5 | AG50: 3 | AH50: 3 | AI50: 4 | AJ50: 3 | AK50: 4 | AL50: 4 | AM50: 3 | AN50: 4 | AO50: 4 | AP50: 4 | AQ50: 4 | AR50: 3 | AS50: 3 | AT50: 3 | AU50: 2 | AV50: 5 | AW50: 3 | AX50: 2 | AY50: 3 | AZ50: 3
B51: ID050 | C51: 5 | D51: 4 | E51: 4 | F51: 5 | G51: 2 | H51: 5 | I51: 5 | J51: 5 | K51: 4 | L51: 4 | M51: 4 | N51: 4 | O51: 5 | P51: 3 | Q51: 5 | R51: 4 | S51: 5 | T51: 3 | U51: 4 | V51: 4 | W51: 4 | X51: 4 | Y51: 4 | Z51: 4 | AA51: 5 | AB51: 4 | AC51: 5 | AD51: 5 | AE51: 4 | AF51: 5 | AG51: 5 | AH51: 4 | AI51: 4 | AJ51: 5 | AK51: 4 | AL51: 4 | AM51: 4 | AN51: 5 | AO51: 4 | AP51: 5 | AQ51: 4 | AR51: 4 | AS51: 4 | AT51: 4 | AU51: 2 | AV51: 5 | AW51: 3 | AX51: 1 | AY51: 1 | AZ51: 4
B52: ID051 | C52: 4 | D52: 2 | E52: 4 | F52: 3 | G52: 3 | H52: 4 | I52: 4 | J52: 3 | K52: 4 | L52: 3 | M52: 3 | N52: 5 | O52: 4 | P52: 2 | Q52: 2 | R52: 3 | S52: 3 | T52: 3 | U52: 4 | V52: 3 | W52: 2 | X52: 3 | Y52: 4 | Z52: 4 | AA52: 3 | AB52: 3 | AC52: 3 | AD52: 2 | AE52: 2 | AF52: 3 | AG52: 4 | AH52: 4 | AI52: 4 | AJ52: 3 | AK52: 3 | AL52: 4 | AM52: 3 | AN52: 4 | AO52: 4 | AP52: 3 | AQ52: 4 | AR52: 3 | AS52: 3 | AT52: 2 | AU52: 2 | AV52: 5 | AW52: 2 | AX52: 1 | AY52: 3 | AZ52: 4
B53: ID052 | C53: 5 | D53: 4 | E53: 4 | F53: 5 | G53: 2 | H53: 5 | I53: 5 | J53: 5 | K53: 4 | L53: 4 | M53: 4 | N53: 4 | O53: 5 | P53: 4 | Q53: 5 | R53: 4 | S53: 5 | T53: 3 | U53: 4 | V53: 4 | W53: 4 | X53: 4 | Y53: 4 | Z53: 4 | AA53: 5 | AB53: 4 | AC53: 5 | AD53: 5 | AE53: 4 | AF53: 5 | AG53: 5 | AH53: 4 | AI53: 4 | AJ53: 5 | AK53: 4 | AL53: 4 | AM53: 4 | AN53: 4 | AO53: 5 | AP53: 4 | AQ53: 5 | AR53: 4 | AS53: 4 | AT53: 4 | AU53: 2 | AV53: 4 | AW53: 2 | AX53: 1 | AY53: 3 | AZ53: 3
B54: ID053 | C54: 5 | D54: 4 | E54: 1 | F54: 3 | G54: 1 | H54: 4 | I54: 4 | J54: 4 | K54: 4 | L54: 4 | M54: 4 | N54: 3 | O54: 3 | P54: 3 | Q54: 3 | R54: 2 | S54: 4 | T54: 2 | U54: 3 | V54: 3 | W54: 1 | X54: 2 | Y54: 3 | Z54: 4 | AA54: 3 | AB54: 2 | AC54: 3 | AD54: 3 | AE54: 4 | AF54: 5 | AG54: 1 | AH54: 2 | AI54: 3 | AJ54: 2 | AK54: 3 | AL54: 5 | AM54: 4 | AN54: 2 | AO54: 3 | AP54: 3 | AQ54: 3 | AR54: 2 | AS54: 2 | AT54: 4 | AU54: 2 | AV54: 3 | AW54: 2 | AX54: 2 | AY54: 3 | AZ54: 5
B55: ID054 | C55: 4 | D55: 5 | E55: 3 | F55: 4 | G55: 4 | H55: 4 | I55: 5 | J55: 4 | K55: 4 | L55: 5 | M55: 4 | N55: 4 | O55: 4 | P55: 5 | Q55: 5 | R55: 5 | S55: 4 | T55: 3 | U55: 5 | V55: 4 | W55: 4 | X55: 4 | Y55: 4 | Z55: 3 | AA55: 4 | AB55: 3 | AC55: 4 | AD55: 4 | AE55: 4 | AF55: 5 | AG55: 4 | AH55: 4 | AI55: 5 | AJ55: 4 | AK55: 3 | AL55: 4 | AM55: 5 | AN55: 4 | AO55: 5 | AP55: 4 | AQ55: 4 | AR55: 3 | AS55: 3 | AT55: 5 | AU55: 2 | AV55: 2 | AW55: 3 | AX55: 1 | AY55: 3 | AZ55: 4
B56: ID055 | C56: 2 | D56: 3 | E56: 4 | F56: 2 | G56: 4 | H56: 3 | I56: 2 | J56: 3 | K56: 4 | L56: 3 | M56: 4 | N56: 5 | O56: 5 | P56: 3 | Q56: 5 | R56: 4 | S56: 5 | T56: 4 | U56: 5 | V56: 4 | W56: 5 | X56: 3 | Y56: 5 | Z56: 5 | AA56: 3 | AB56: 4 | AC56: 4 | AD56: 3 | AE56: 3 | AF56: 4 | AG56: 3 | AH56: 3 | AI56: 3 | AJ56: 4 | AK56: 3 | AL56: 4 | AM56: 4 | AN56: 4 | AO56: 5 | AP56: 4 | AQ56: 4 | AR56: 3 | AS56: 3 | AT56: 3 | AU56: 2 | AV56: 3 | AW56: 2 | AX56: 1 | AY56: 3 | AZ56: 5
B57: ID056 | C57: 1 | D57: 1 | E57: 1 | F57: 1 | G57: 1 | H57: 5 | I57: 5 | J57: 3 | K57: 2 | L57: 5 | M57: 5 | N57: 5 | O57: 4 | P57: 5 | Q57: 5 | R57: 5 | S57: 5 | T57: 3 | U57: 5 | V57: 4 | W57: 4 | X57: 3 | Y57: 1 | Z57: 1 | AA57: 2 | AB57: 2 | AC57: 5 | AD57: 5 | AE57: 5 | AF57: 5 | AG57: 2 | AH57: 2 | AI57: 3 | AJ57: 5 | AK57: 4 | AL57: 5 | AM57: 3 | AN57: 4 | AO57: 5 | AP57: 4 | AQ57: 5 | AR57: 2 | AS57: 1 | AT57: 5 | AU57: 2 | AV57: 3 | AW57: 2 | AX57: 1 | AY57: 1 | AZ57: 5
B58: ID057 | C58: 1 | D58: 1 | E58: 4 | F58: 3 | G58: 4 | H58: 4 | I58: 4 | J58: 4 | K58: 5 | L58: 3 | M58: 3 | N58: 5 | O58: 5 | P58: 4 | Q58: 2 | R58: 3 | S58: 2 | T58: 5 | U58: 5 | V58: 4 | W58: 3 | X58: 5 | Y58: 5 | Z58: 4 | AA58: 4 | AB58: 3 | AC58: 4 | AD58: 4 | AE58: 3 | AF58: 5 | AG58: 5 | AH58: 3 | AI58: 3 | AJ58: 2 | AK58: 2 | AL58: 5 | AM58: 3 | AN58: 4 | AO58: 5 | AP58: 4 | AQ58: 3 | AR58: 2 | AS58: 2 | AT58: 4 | AU58: 2 | AV58: 5 | AW58: 2 | AX58: 1 | AY58: 3 | AZ58: 4
B59: ID058 | C59: 1 | D59: 1 | E59: 4 | F59: 3 | G59: 4 | H59: 4 | I59: 4 | J59: 4 | K59: 5 | L59: 3 | M59: 3 | N59: 5 | O59: 5 | P59: 3 | Q59: 2 | R59: 4 | S59: 2 | T59: 5 | U59: 5 | V59: 4 | W59: 3 | X59: 5 | Y59: 5 | Z59: 3 | AA59: 3 | AB59: 5 | AC59: 3 | AD59: 4 | AE59: 4 | AF59: 5 | AG59: 5 | AH59: 3 | AI59: 3 | AJ59: 4 | AK59: 4 | AL59: 3 | AM59: 1 | AN59: 4 | AO59: 5 | AP59: 4 | AQ59: 3 | AR59: 2 | AS59: 2 | AT59: 4 | AU59: 2 | AV59: 5 | AW59: 2 | AX59: 1 | AY59: 3 | AZ59: 4
B60: ID059 | C60: 1 | D60: 1 | E60: 4 | F60: 3 | G60: 4 | H60: 4 | I60: 4 | J60: 4 | K60: 5 | L60: 3 | M60: 3 | N60: 5 | O60: 5 | P60: 3 | Q60: 2 | R60: 4 | S60: 2 | T60: 5 | U60: 5 | V60: 4 | W60: 3 | X60: 5 | Y60: 5 | Z60: 3 | AA60: 3 | AB60: 5 | AC60: 3 | AD60: 4 | AE60: 4 | AF60: 5 | AG60: 5 | AH60: 3 | AI60: 3 | AJ60: 4 | AK60: 4 | AL60: 5 | AM60: 3 | AN60: 4 | AO60: 5 | AP60: 4 | AQ60: 3 | AR60: 2 | AS60: 2 | AT60: 4 | AU60: 2 | AV60: 5 | AW60: 2 | AX60: 1 | AY60: 1 | AZ60: 4
B61: ID060 | C61: 4 | D61: 5 | E61: 3 | F61: 4 | G61: 4 | H61: 4 | I61: 5 | J61: 4 | K61: 4 | L61: 5 | M61: 4 | N61: 4 | O61: 4 | P61: 5 | Q61: 5 | R61: 5 | S61: 4 | T61: 3 | U61: 5 | V61: 4 | W61: 4 | X61: 4 | Y61: 4 | Z61: 3 | AA61: 4 | AB61: 3 | AC61: 4 | AD61: 3 | AE61: 3 | AF61: 4 | AG61: 4 | AH61: 4 | AI61: 5 | AJ61: 4 | AK61: 3 | AL61: 4 | AM61: 5 | AN61: 4 | AO61: 5 | AP61: 4 | AQ61: 4 | AR61: 3 | AS61: 3 | AT61: 5 | AU61: 2 | AV61: 3 | AW61: 3 | AX61: 1 | AY61: 1 | AZ61: 4
B62: ID061 | C62: 4 | D62: 5 | E62: 3 | F62: 4 | G62: 4 | H62: 4 | I62: 5 | J62: 4 | K62: 4 | L62: 5 | M62: 4 | N62: 4 | O62: 4 | P62: 5 | Q62: 5 | R62: 5 | S62: 4 | T62: 3 | U62: 5 | V62: 4 | W62: 4 | X62: 4 | Y62: 4 | Z62: 3 | AA62: 4 | AB62: 3 | AC62: 4 | AD62: 3 | AE62: 3 | AF62: 4 | AG62: 4 | AH62: 4 | AI62: 5 | AJ62: 4 | AK62: 3 | AL62: 4 | AM62: 5 | AN62: 4 | AO62: 5 | AP62: 4 | AQ62: 4 | AR62: 3 | AS62: 3 | AT62: 5 | AU62: 2 | AV62: 3 | AW62: 2 | AX62: 1 | AY62: 2 | AZ62: 4
... B72: ID071 | C72: 4 | D72: 4 | E72: 3 | F72: 4 | G72: 4 | H72: 4 | I72: 4 | J72: 4 | K72: 4 | L72: 4 | M72: 4 | N72: 4 | O72: 4 | P72: 4 | Q72: 4 | R72: 4 | S72: 4 | T72: 4 | U72: 4 | V72: 4 | W72: 4 | X72: 4 | Y72: 4 | Z72: 3 | AA72: 3 | AB72: 3 | AC72: 4 | AD72: 5 | AE72: 4 | AF72: 5 | AG72: 3 | AH72: 4 | AI72: 4 | AJ72: 5 | AK72: 4 | AL72: 4 | AM72: 4 | AN72: 4 | AO72: 4 | AP72: 5 | AQ72: 5 | AR72: 4 | AS72: 4 | AT72: 5 | AU72: 2 | AV72: 2 | AW72: 3 | AX72: 2 | AY72: 1 | AZ72: 5
B73: ID072 | C73: 3 | D73: 3 | E73: 3 | F73: 3 | G73: 3 | H73: 3 | I73: 2 | J73: 3 | K73: 2 | L73: 3 | M73: 3 | N73: 3 | O73: 4 | P73: 4 | Q73: 4 | R73: 4 | S73: 5 | T73: 4 | V73: 2 | W73: 2 | X73: 3 | Y73: 3 | Z73: 2 | AA73: 3 | AB73: 3 | AC73: 4 | AD73: 3 | AE73: 3 | AF73: 4 | AG73: 3 | AH73: 3 | AI73: 3 | AJ73: 2 | AK73: 2 | AL73: 4 | AM73: 5 | AN73: 4 | AO73: 5 | AP73: 5 | AQ73: 2 | AR73: 2 | AS73: 2 | AT73: 4 | AU73: 2 | AV73: 2 | AW73: 3 | AX73: 2 | AY73: 3 | AZ73: 5
B74: ID073 | C74: 1 | D74: 1 | E74: 5 | F74: 1 | G74: 1 | H74: 5 | I74: 5 | J74: 5 | K74: 5 | L74: 5 | M74: 5 | N74: 5 | O74: 5 | P74: 4 | Q74: 4 | R74: 4 | S74: 4 | T74: 4 | U74: 5 | V74: 5 | W74: 5 | X74: 5 | Y74: 5 | Z74: 5 | AA74: 5 | AB74: 3 | AC74: 3 | AD74: 3 | AE74: 5 | AF74: 5 | AG74: 3 | AH74: 3 | AI74: 1 | AJ74: 1 | AK74: 1 | AL74: 1 | AM74: 1 | AN74: 5 | AO74: 5 | AP74: 5 | AQ74: 5 | AR74: 1 | AS74: 1 | AT74: 1 | AU74: 2 | AV74: 4 | AW74: 3 | AX74: 2 | AY74: 3 | AZ74: 4
B75: ID074 | C75: 4 | D75: 4 | E75: 1 | F75: 3 | G75: 3 | H75: 4 | I75: 4 | J75: 5 | K75: 4 | L75: 5 | M75: 3 | N75: 5 | O75: 5 | P75: 3 | Q75: 5 | R75: 3 | S75: 4 | T75: 2 | U75: 5 | V75: 5 | W75: 4 | X75: 5 | Y75: 4 | Z75: 3 | AA75: 5 | AB75: 3 | AC75: 5 | AD75: 3 | AE75: 4 | AF75: 4 | AG75: 3 | AH75: 4 | AI75: 5 | AJ75: 5 | AK75: 5 | AL75: 3 | AM75: 2 | AN75: 5 | AO75: 5 | AP75: 5 | AQ75: 4 | AR75: 3 | AS75: 3 | AT75: 4 | AU75: 2 | AV75: 4 | AW75: 3 | AX75: 2 | AY75: 1 | AZ75: 4
B76: ID075 | C76: 4 | D76: 4 | E76: 1 | F76: 3 | G76: 3 | H76: 4 | I76: 4 | J76: 3 | K76: 4 | L76: 5 | M76: 3 | N76: 5 | O76: 5 | P76: 3 | Q76: 4 | R76: 2 | S76: 4 | T76: 2 | U76: 3 | V76: 3 | W76: 4 | X76: 5 | Y76: 4 | Z76: 3 | AA76: 5 | AB76: 3 | AC76: 5 | AD76: 4 | AE76: 4 | AF76: 4 | AG76: 4 | AH76: 5 | AI76: 2 | AJ76: 2 | AK76: 2 | AL76: 5 | AM76: 3 | AN76: 4 | AO76: 4 | AP76: 4 | AQ76: 4 | AR76: 3 | AS76: 3 | AT76: 4 | AU76: 2 | AV76: 5 | AW76: 2 | AX76: 2 | AY76: 3 | AZ76: 4
B77: ID076 | C77: 3 | D77: 1 | E77: 1 | F77: 2 | G77: 1 | H77: 1 | I77: 1 | J77: 3 | K77: 1 | L77: 5 | M77: 1 | N77: 3 | O77: 1 | P77: 5 | Q77: 4 | R77: 2 | S77: 5 | T77: 5 | U77: 1 | V77: 1 | W77: 3 | X77: 5 | Y77: 3 | Z77: 3 | AA77: 2 | AB77: 3 | AC77: 3 | AD77: 5 | AE77: 5 | AF77: 5 | AG77: 5 | AH77: 2 | AI77: 5 | AJ77: 2 | AK77: 2 | AL77: 1 | AM77: 4 | AN77: 5 | AO77: 5 | AP77: 5 | AQ77: 1 | AR77: 2 | AS77: 2 | AT77: 5 | AU77: 2 | AV77: 2 | AW77: 3 | AX77: 2 | AY77: 1 | AZ77: 3
B78: ID077 | C78: 5 | D78: 3 | E78: 3 | F78: 3 | G78: 2 | H78: 5 | I78: 4 | J78: 4 | K78: 4 | L78: 4 | M78: 4 | N78: 5 | O78: 4 | P78: 3 | Q78: 3 | R78: 2 | S78: 3 | T78: 1 | U78: 5 | V78: 5 | W78: 5 | X78: 5 | Y78: 5 | Z78: 5 | AA78: 5 | AB78: 4 | AC78: 5 | AD78: 4 | AE78: 4 | AF78: 5 | AG78: 5 | AH78: 4 | AI78: 5 | AJ78: 5 | AK78: 5 | AL78: 5 | AM78: 4 | AN78: 5 | AO78: 5 | AP78: 5 | AQ78: 5 | AR78: 3 | AS78: 3 | AT78: 4 | AU78: 2 | AV78: 4 | AW78: 2 | AX78: 2 | AY78: 2 | AZ78: 3
B79: ID078 | C79: 5 | D79: 3 | E79: 2 | F79: 3 | G79: 5 | H79: 3 | I79: 3 | J79: 3 | K79: 4 | L79: 4 | M79: 5 | N79: 4 | O79: 5 | P79: 4 | Q79: 3 | R79: 3 | S79: 3 | T79: 4 | U79: 5 | V79: 5 | W79: 5 | X79: 4 | Y79: 5 | Z79: 5 | AA79: 4 | AB79: 4 | AC79: 4 | AD79: 4 | AE79: 4 | AF79: 5 | AG79: 4 | AH79: 3 | AI79: 3 | AJ79: 3 | AK79: 5 | AL79: 5 | AM79: 5 | AN79: 4 | AO79: 4 | AP79: 4 | AQ79: 5 | AR79: 3 | AS79: 3 | AT79: 5 | AU79: 2 | AV79: 5 | AW79: 3 | AX79: 2 | AY79: 2 | AZ79: 5
...

Sheet PCA
A1: Factor Analysis - Principal Component Extraction
B5: 1.Delay in delivering material to construction site | C5: 2.Monopoly of material by some suppliers | D5: 3.Prices fluctuation | E5: 4.Types of material availability at local market | F5: 5.Lack of consultant’s knowledge of available materials | G5: 6.Low productivity | H5: 7.Poor work execution | I5: 8.Shortage of laborers | J5: 9.Mistakes happens during construction phase | K5: 10.Unavailability of equipment | L5: 11.Lack of engineering experience | M5: 12.Construction cost underestimation | N5: 13.Poor site management | O5: 14.Delayed payment for completed work | P5: 15.Cash flow problem during construction | Q5: 16.High rate of interest | R5: 17.Contractor’s financial difficulties | S5: 18.Increase in salaries of skilled laborers | T5: 19.Change design | U5: 20.Errors and omission in design | V5: 21.Incomplete design drawings and specifications at tendering stage | W5: 22.Delay in preparation and approval of drawing | X5: 23.Inaccurate quantity take-off | Y5: 24.Long period from planning of project to construction | Z5: 25.Delays in issuing information to the contractor during construction stage | AA5: 26.No practical use of earned value management system | AB5: 27.Lack of cost planning/monitoring during pre and post contract stage | AC5: 28.Poor communication between client, consultant and contractor | AD5: 29.Insufficient coordination between local authority who is responsible about road projects and service authorities | AE5: 30.Delays in decisions making by the approval authorities | AF5: 31.Change schedule | AG5: 32.Stoppages because of work being rejected by consultant | AH5: 33.Lowest bid price | AI5: 34.Insufficient time for preparation of contract documents | AJ5: 35.Discrepancies in contract documents | AK5: 36.Underestimation of time for completion of project | AL5: 37.Extension of time with cost claims | AM5: 38.Scope and specification changes | AN5: 39.Changes in client requirements | AO5: 40.Frequency of variation orders and additional works | AP5: 41.Rework due to error in execution | AQ5: 42.Weather conditions | AR5: 43.Accidents during construction | AS5: 44.Delay in getting NOCs from different government authorities | AT5: Type of Organization | AU5: Respondents designation | AV5: Indicate the highest formal qualification | AW5: Location of organization | AX5: Relevant working experience
A6: Mean | B6: 3.08 | C6: 2.99 | D6: 2.74 | E6: 2.92 | F6: 2.83 | G6: 3.45 | H6: 3.53 | I6: 3.41 | J6: 3.33 | K6: 3.42 | L6: 3.51 | M6: 3.79 | N6: 3.77 | O6: 3.61 | P6: 3.63 | Q6: 3.17 | R6: 3.58 | S6: 2.76 | T6: 3.81 | U6: 3.47 | V6: 3.52 | W6: 3.62 | X6: 3.64 | Y6: 3.48 | Z6: 3.25 | AA6: 3.06 | AB6: 3.46 | AC6: 3.32 | AD6: 3.55 | AE6: 4.03 | AF6: 3.28 | AG6: 3.1 | AH6: 3.28 | AI6: 3.18 | AJ6: 3.19 | AK6: 3.66 | AL6: 3.65 | AM6: 3.94 | AN6: 4.07 | AO6: 3.91 | AP6: 3.56 | AQ6: 2.49 | AR6: 2.7 | AS6: 3.66 | AT6: 1.94 | AU6: 3.19 | AV6: 2.38 | AW6: 2.15 | AX6: 4.05
A7: Std dev | B7: 1.261996 | C7: 1.334781 | D7: 1.117803 | E7: 1.058144 | F7: 1.255893 | G7: 1.092402 | H7: 1.191544 | I7: 1.114803 | J7: 1.208982 | K7: 1.171328 | L7: 1.18004 | M7: 1.203593 | N7: 1.220092 | O7: 0.993181 | P7: 1.123866 | Q7: 1.227536 | R7: 1.1653 | S7: 1.095553 | T7: 1.00634 | U7: 1.143285 | V7: 1.073714 | W7: 0.991543 | X7: 0.996794 | Y7: 0.998965 | Z7: 1.010289 | AA7: 0.984215 | AB7: 0.976983 | AC7: 1.236769 | AD7: 1.066304 | AE7: 0.934051 | AF7: 1.030558 | AG7: 1.09874 | AH7: 1.22252 | AI7: 1.142251 | AJ7: 1.047808 | AK7: 0.992536 | AL7: 0.994766 | AM7: 0.902081 | AN7: 0.954237 | AO7: 0.910882 | AP7: 1.03884 | AQ7: 1.026872 | AR7: 1.132335 | AS7: 1.100218 | AT7: 0.752618 | AU7: 1.31058 | AV7: 0.580469 | AW7: 0.824858 | AX7: 1.121673
A8: Skewness | B8: -0.35981 | C8: 0.012937 | D8: -0.17796 | E8: -0.19224 | F8: -0.08853 | G8: -0.72048 | H8: -0.77222 | I8: -0.60971 | J8: -0.5607 | K8: -0.55018 | L8: -0.76867 | M8: -0.84061 | N8: -0.96303 | O8: -0.41448 | P8: -0.70587 | Q8: -0.23326 | R8: -0.72541 | S8: 0.175116 | T8: -0.72531 | U8: -0.56682 | V8: -0.46137 | W8: -0.45528 | X8: -0.64329 | Y8: -0.18765 | Z8: -0.15061 | AA8: -0.1132 | AB8: -0.44213 | AC8: -0.47709 | AD8: -0.45599 | AE8: -0.79229 | AF8: -0.35032 | AG8: -0.30751 | AH8: -0.2018 | AI8: -0.04753 | AJ8: -0.0886 | AK8: -0.72844 | AL8: -0.55498 | AM8: -0.82294 | AN8: -0.733 | AO8: -0.4986 | AP8: -0.52387 | AQ8: 0.285851 | AR8: 0.497504 | AS8: -0.68377 | AT8: 0.104247 | AU8: 0.25345 | AV8: 0.571734 | AW8: -0.29413 | AX8: -1.25133
A9: Kurtosis | B9: -1.08886 | C9: -1.14576 | D9: -0.71607 | E9: -0.40074 | F9: -1.02825 | G9: -0.18631 | H9: -0.2154 | I9: -0.10683 | J9: -0.57079 | K9: -0.34221 | L9: -0.19563 | M9: -0.13374 | N9: 0.028493 | O9: -0.15998 | P9: -0.20726 | Q9: -0.86994 | R9: -0.3229 | S9: -0.59223 | T9: 0.025995 | U9: -0.55378 | V9: -0.5538 | W9: -0.48209 | X9: 0.327286 | Y9: -0.52799 | Z9: -0.43982 | AA9: -0.09886 | AB9: -0.28377 | AC9: -0.70887 | AD9: -0.47317 | AE9: 0.308968 | AF9: -0.36556 | AG9: -0.73755 | AH9: -0.92286 | AI9: -0.87091 | AJ9: -0.75921 | AK9: 0.279245 | AL9: -0.05006 | AM9: 0.384649 | AN9: -0.44941 | AO9: -0.26897 | AP9: -0.13618 | AQ9: -0.4768 | AR9: -0.48746 | AS9: -0.14256 | AT9: -1.21779 | AU9: -1.47001 | AV9: -0.00278 | AW9: -1.47084 | AX9: 0.986304
A11: Correlation Matrix
B13: 1.Delay in delivering material to construction site | C13: 2.Monopoly of material by some suppliers | D13: 3.Prices fluctuation | E13: 4.Types of material availability at local market | F13: 5.Lack of consultant’s knowledge of available materials | G13: 6.Low productivity | H13: 7.Poor work execution | I13: 8.Shortage of laborers | J13: 9.Mistakes happens during construction phase | K13: 10.Unavailability of equipment | L13: 11.Lack of engineering experience | M13: 12.Construction cost underestimation | N13: 13.Poor site management | O13: 14.Delayed payment for completed work | P13: 15.Cash flow problem during construction | Q13: 16.High rate of interest | R13: 17.Contractor’s financial difficulties | S13: 18.Increase in salaries of skilled laborers | T13: 19.Change design | U13: 20.Errors and omission in design | V13: 21.Incomplete design drawings and specifications at tendering stage | W13: 22.Delay in preparation and approval of drawing | X13: 23.Inaccurate quantity take-off | Y13: 24.Long period from planning of project to construction | Z13: 25.Delays in issuing information to the contractor during construction stage | AA13: 26.No practical use of earned value management system | AB13: 27.Lack of cost planning/monitoring during pre and post contract stage | AC13: 28.Poor communication between client, consultant and contractor | AD13: 29.Insufficient coordination between local authority who is responsible about road projects and service authorities | AE13: 30.Delays in decisions making by the approval authorities | AF13: 31.Change schedule | AG13: 32.Stoppages because of work being rejected by consultant | AH13: 33.Lowest bid price | AI13: 34.Insufficient time for preparation of contract documents | AJ13: 35.Discrepancies in contract documents | AK13: 36.Underestimation of time for completion of project | AL13: 37.Extension of time with cost claims | AM13: 38.Scope and specification changes | AN13: 39.Changes in client requirements | AO13: 40.Frequency of variation orders and additional works | AP13: 41.Rework due to error in execution | AQ13: 42.Weather conditions | AR13: 43.Accidents during construction | AS13: 44.Delay in getting NOCs from different government authorities | AT13: Type of Organization | AU13: Respondents designation | AV13: Indicate the highest formal qualification | AW13: Location of organization | AX13: Relevant working experience
A14: 1.Delay in delivering material to construction site | B14: 1 | C14: 0.617447 | D14: 0.213695 | E14: 0.673332 | F14: 0.374378 | G14: 0.484591 | H14: 0.538329 | I14: 0.547602 | J14: 0.402341 | K14: 0.470701 | L14: 0.436309 | M14: 0.308012 | N14: 0.276926 | O14: 0.125762 | P14: 0.184925 | Q14: 0.058699 | R14: 0.086557 | S14: 0.243634 | T14: 0.15312 | U14: 0.074863 | V14: 0.029097 | W14: 0.088645 | X14: -0.13842 | Y14: -0.07117 | Z14: 0.263414 | AA14: 0.150097 | AB14: 0.273813 | AC14: 0.324388 | AD14: 0.186236 | AE14: 0.106013 | AF14: 0.022708 | AG14: 0.367218 | AH14: 0.400073 | AI14: 0.240698 | AJ14: 0.287874 | AK14: 0.313114 | AL14: 0.323179 | AM14: 0.103723 | AN14: 0.181608 | AO14: 0.159553 | AP14: 0.261497 | AQ14: 0.344058 | AR14: 0.42143 | AS14: 0.340472 | AT14: 0.164655 | AU14: 0.01621 | AV14: 0.120672 | AW14: -0.065 | AX14: -0.15217
A15: 2.Monopoly of material by some suppliers | B15: 0.617447 | C15: 1 | D15: 0.334336 | E15: 0.558668 | F15: 0.426873 | G15: 0.343882 | H15: 0.384931 | I15: 0.393506 | J15: 0.314199 | K15: 0.362904 | L15: 0.427641 | M15: 0.197617 | N15: 0.297861 | O15: 0.101421 | P15: 0.199332 | Q15: 0.146866 | R15: 0.147563 | S15: 0.084895 | T15: 0.303899 | U15: 0.221947 | V15: 0.044296 | W15: -0.04365 | X15: 0.015877 | Y15: -0.05185 | Z15: 0.231034 | AA15: -0.0423 | AB15: 0.209817 | AC15: 0.180847 | AD15: 0.073655 | AE15: -0.1077 | AF15: -0.07324 | AG15: 0.307204 | AH15: 0.300923 | AI15: 0.17474 | AJ15: 0.148534 | AK15: 0.322445 | AL15: 0.317957 | AM15: -0.13152 | AN15: 0.10813 | AO15: 0.033642 | AP15: 0.179366 | AQ15: 0.335591 | AR15: 0.421812 | AS15: 0.350091 | AT15: 0.077743 | AU15: -0.00134 | AV15: 0.122298 | AW15: 0.154389 | AX15: -0.18119
A16: 3.Prices fluctuation | B16: 0.213695 | C16: 0.334336 | D16: 1 | E16: 0.511606 | F16: 0.39448 | G16: 0.34846 | H16: 0.413956 | I16: 0.279592 | J16: 0.400803 | K16: 0.230993 | L16: 0.382316 | M16: 0.358718 | N16: 0.36283 | O16: -0.0595 | P16: 0.002948 | Q16: 0.061672 | R16: 0.004653 | S16: 0.267269 | T16: 0.265123 | U16: 0.089193 | V16: 0.131057 | W16: 0.023002 | X16: 0.045399 | Y16: 0.108239 | Z16: 0.039962 | AA16: 0.25724 | AB16: 0.18405 | AC16: 0.180387 | AD16: 0.076737 | AE16: -0.11429 | AF16: 0.051891 | AG16: 0.14818 | AH16: 0.174717 | AI16: 0.110398 | AJ16: 0.061732 | AK16: 0.251131 | AL16: 0.088153 | AM16: 0.144634 | AN16: 0.205128 | AO16: -0.0201 | AP16: 0.223326 | AQ16: 0.109573 | AR16: 0.178412 | AS16: -0.00079 | AT16: 0.105309 | AU16: 0.264537 | AV16: -0.02573 | AW16: 0.235288 | AX16: -0.25457
A17: 4.Types of material availability at local market | B17: 0.673332 | C17: 0.558668 | D17: 0.511606 | E17: 1 | F17: 0.55855 | G17: 0.527909 | H17: 0.625926 | I17: 0.531127 | J17: 0.392543 | K17: 0.462761 | L17: 0.515672 | M17: 0.360599 | N17: 0.448709 | O17: 0.099347 | P17: 0.17308 | Q17: 0.147487 | R17: 0.134703 | S17: 0.263145 | T17: 0.212299 | U17: 0.153376 | V17: 0.110675 | W17: 0.035865 | X17: 0.063933 | Y17: -0.02161 | Z17: 0.30702 | AA17: 0.269866 | AB17: 0.390218 | AC17: 0.374996 | AD17: 0.146989 | AE17: 0.160056 | AF17: 0.153899 | AG17: 0.404253 | AH17: 0.415851 | AI17: 0.303602 | AJ17: 0.278869 | AK17: 0.341506 | AL17: 0.248039 | AM17: 0.120219 | AN17: 0.231206 | AO17: 0.024896 | AP17: 0.312467 | AQ17: 0.389342 | AR17: 0.430293 | AS17: 0.222421 | AT17: 0.235994 | AU17: 0.04087 | AV17: 0.06802 | AW17: 0.05624 | AX17: -0.15982
A18: 5.Lack of consultant’s knowledge of available materials | B18: 0.374378 | C18: 0.426873 | D18: 0.39448 | E18: 0.55855 | F18: 1 | G18: 0.426822 | H18: 0.516328 | I18: 0.421754 | J18: 0.550363 | K18: 0.394762 | L18: 0.497702 | M18: 0.490624 | N18: 0.553822 | O18: 0.163971 | P18: 0.177539 | Q18: 0.433905 | R18: 0.051387 | S18: 0.355682 | T18: 0.467038 | U18: 0.437446 | V18: 0.410275 | W18: 0.285149 | X18: 0.348235 | Y18: 0.042098 | Z18: 0.426336 | AA18: 0.454197 | AB18: 0.45199 | AC18: 0.434222 | AD18: 0.228668 | AE18: 0.088695 | AF18: 0.235763 | AG18: 0.500686 | AH18: 0.357036 | AI18: 0.414392 | AJ18: 0.402695 | AK18: 0.2871 | AL18: 0.274633 | AM18: 0.227963 | AN18: 0.335344 | AO18: 0.188694 | AP18: 0.315329 | AQ18: 0.410886 | AR18: 0.380858 | AS18: 0.2323 | AT18: 0.153973 | AU18: -0.02774 | AV18: -0.00751 | AW18: 0.03796 | AX18: -0.18844
A19: 6.Low productivity | B19: 0.484591 | C19: 0.343882 | D19: 0.34846 | E19: 0.527909 | F19: 0.426822 | G19: 1 | H19: 0.82122 | I19: 0.724846 | J19: 0.702263 | K19: 0.546242 | L19: 0.65229 | M19: 0.660151 | N19: 0.675342 | O19: 0.08175 | P19: 0.098779 | Q19: 0.233492 | R19: 0.043609 | S19: 0.211196 | T19: 0.373471 | U19: 0.18297 | V19: 0.094957 | W19: 0.099699 | X19: 0.07354 | Y19: -0.05932 | Z19: 0.403001 | AA19: 0.258229 | AB19: 0.444134 | AC19: 0.370043 | AD19: 0.382941 | AE19: 0.111805 | AF19: 0.093861 | AG19: 0.327582 | AH19: 0.161801 | AI19: 0.359979 | AJ19: 0.366204 | AK19: 0.456326 | AL19: 0.167462 | AM19: 0.203022 | AN19: 0.242078 | AO19: 0.170312 | AP19: 0.374298 | AQ19: 0.281705 | AR19: 0.233685 | AS19: 0.217358 | AT19: 0.303712 | AU19: 0.053072 | AV19: -0.04144 | AW19: -0.1268 | AX19: 0.093833
A20: 7.Poor work execution | B20: 0.538329 | C20: 0.384931 | D20: 0.413956 | E20: 0.625926 | F20: 0.516328 | G20: 0.82122 | H20: 1 | I20: 0.606889 | J20: 0.681291 | K20: 0.54631 | L20: 0.67464 | M20: 0.594184 | N20: 0.692462 | O20: 0.199402 | P20: 0.18836 | Q20: 0.266013 | R20: 0.134551 | S20: 0.221247 | T20: 0.424654 | U20: 0.231783 | V20: 0.154811 | W20: 0.187002 | X20: 0.086875 | Y20: 0.029888 | Z20: 0.424424 | AA20: 0.324708 | AB20: 0.536029 | AC20: 0.458468 | AD20: 0.36675 | AE20: 0.265599 | AF20: 0.112323 | AG20: 0.428292 | AH20: 0.327125 | AI20: 0.38895 | AJ20: 0.463202 | AK20: 0.483567 | AL20: 0.192141 | AM20: 0.231245 | AN20: 0.346915 | AO20: 0.166011 | AP20: 0.482768 | AQ20: 0.306286 | AR20: 0.300448 | AS20: 0.332622 | AT20: 0.327317 | AU20: 0.091612 | AV20: 0.001858 | AW20: -0.08863 | AX20: -0.02331
A21: 8.Shortage of laborers | B21: 0.547602 | C21: 0.393506 | D21: 0.279592 | E21: 0.531127 | F21: 0.421754 | G21: 0.724846 | H21: 0.606889 | I21: 1 | J21: 0.637295 | K21: 0.692857 | L21: 0.610079 | M21: 0.660787 | N21: 0.543651 | O21: 0.24175 | P21: 0.160673 | Q21: 0.254432 | R21: 0.074707 | S21: 0.366163 | T21: 0.343841 | U21: 0.20507 | V21: 0.092432 | W21: 0.119919 | X21: -0.05228 | Y21: -0.0863 | Z21: 0.355575 | AA21: 0.332783 | AB21: 0.318246 | AC21: 0.435951 | AD21: 0.309141 | AE21: 0.15158 | AF21: 0.264405 | AG21: 0.290272 | AH21: 0.314764 | AI21: 0.428882 | AJ21: 0.331026 | AK21: 0.245979 | AL21: 0.198476 | AM21: 0.259149 | AN21: 0.272815 | AO21: 0.196012 | AP21: 0.19772 | AQ21: 0.359866 | AR21: 0.31944 | AS21: 0.331813 | AT21: 0.250174 | AU21: -0.15073 | AV21: 0.132628 | AW21: -0.12448 | AX21: 0.058905
A22: 9.Mistakes happens during construction phase | B22: 0.402341 | C22: 0.314199 | D22: 0.400803 | E22: 0.392543 | F22: 0.550363 | G22: 0.702263 | H22: 0.681291 | I22: 0.637295 | J22: 1 | K22: 0.602859 | L22: 0.640484 | M22: 0.716775 | N22: 0.57909 | O22: -0.06243 | P22: 0.05619 | Q22: 0.30667 | R22: -0.10843 | S22: 0.238233 | T22: 0.463957 | U22: 0.354787 | V22: 0.182947 | W22: 0.175382 | X22: 0.260035 | Y22: 0.04027 | Z22: 0.337708 | AA22: 0.380576 | AB22: 0.475915 | AC22: 0.486931 | AD22: 0.362106 | AE22: 0.041629 | AF22: 0.166739 | AG22: 0.389531 | AH22: 0.217027 | AI22: 0.38808 | AJ22: 0.440433 | AK22: 0.510131 | AL22: 0.101647 | AM22: 0.173653 | AN22: 0.276445 | AO22: 0.244472 | AP22: 0.358397 | AQ22: 0.346162 | AR22: 0.320782 | AS22: 0.107286 | AT22: 0.125707 | AU22: 0.072288 | AV22: 0.05749 | AW22: -0.03594 | AX22: -0.10373
A23: 10.Unavailability of equipment | B23: 0.470701 | C23: 0.362904 | D23: 0.230993 | E23: 0.462761 | F23: 0.394762 | G23: 0.546242 | H23: 0.54631 | I23: 0.692857 | J23: 0.602859 | K23: 1 | L23: 0.534699 | M23: 0.592702 | N23: 0.392132 | O23: 0.240034 | P23: 0.362282 | Q23: 0.338058 | R23: 0.334682 | S23: 0.329406 | T23: 0.201274 | U23: 0.231534 | V23: 0.19579 | W23: 0.196954 | X23: 0.135718 | Y23: -0.09845 | Z23: 0.278545 | AA23: 0.355037 | AB23: 0.526397 | AC23: 0.641276 | AD23: 0.418262 | AE23: 0.066973 | AF23: 0.263137 | AG23: 0.326977 | AH23: 0.329632 | AI23: 0.398407 | AJ23: 0.35683 | AK23: 0.255843 | AL23: 0.242508 | AM23: 0.248417 | AN23: 0.36385 | AO23: 0.263656 | AP23: 0.258042 | AQ23: 0.394698 | AR23: 0.264021 | AS23: 0.369401 | AT23: 0.157806 | AU23: -0.04228 | AV23: 0.154881 | AW23: -0.15021 | AX23: -0.07452
A24: 11.Lack of engineering experience | B24: 0.436309 | C24: 0.427641 | D24: 0.382316 | E24: 0.515672 | F24: 0.497702 | G24: 0.65229 | H24: 0.67464 | I24: 0.610079 | J24: 0.640484 | K24: 0.534699 | L24: 1 | M24: 0.673701 | N24: 0.742574 | O24: 0.15664 | P24: 0.231625 | Q24: 0.39417 | R24: 0.170229 | S24: 0.224811 | T24: 0.367693 | U24: 0.292584 | V24: 0.274944 | W24: -0.0177 | X24: 0.109076 | Y24: 0.129685 | Z24: 0.366931 | AA24: 0.309221 | AB24: 0.457121 | AC24: 0.50896 | AD24: 0.334607 | AE24: 0.159702 | AF24: 0.073713 | AG24: 0.260559 | AH24: 0.187557 | AI24: 0.442714 | AJ24: 0.486403 | AK24: 0.426793 | AL24: 0.192961 | AM24: 0.017981 | AN24: 0.209146 | AO24: 0.124185 | AP24: 0.466641 | AQ24: 0.383385 | AR24: 0.435719 | AS24: 0.23868 | AT24: 0.358892 | AU24: -0.03318 | AV24: -0.00639 | AW24: -0.10328 | AX24: 0.004912
A25: 12.Construction cost underestimation | B25: 0.308012 | C25: 0.197617 | D25: 0.358718 | E25: 0.360599 | F25: 0.490624 | G25: 0.660151 | H25: 0.594184 | I25: 0.660787 | J25: 0.716775 | K25: 0.592702 | L25: 0.673701 | M25: 1 | N25: 0.708867 | O25: 0.007546 | P25: 0.051844 | Q25: 0.37198 | R25: 0.010037 | S25: 0.304953 | T25: 0.439861 | U25: 0.249239 | V25: 0.302513 | W25: 0.224564 | X25: 0.195931 | Y25: 0.089976 | Z25: 0.301563 | AA25: 0.385961 | AB25: 0.439367 | AC25: 0.446511 | AD25: 0.331241 | AE25: 0.086707 | AF25: 0.208261 | AG25: 0.304288 | AH25: 0.229953 | AI25: 0.461196 | AJ25: 0.434186 | AK25: 0.411536 | AL25: 0.065903 | AM25: 0.369358 | AN25: 0.420076 | AO25: 0.276308 | AP25: 0.392301 | AQ25: 0.404163 | AR25: 0.433821 | AS25: 0.187331 | AT25: 0.471876 | AU25: 0.049303 | AV25: -0.10733 | AW25: -0.17828 | AX25: -0.03834
... A62: Relevant working experience | B62: -0.15217 | C62: -0.18119 | D62: -0.25457 | E62: -0.15982 | F62: -0.18844 | G62: 0.093833 | H62: -0.02331 | I62: 0.058905 | J62: -0.10373 | K62: -0.07452 | L62: 0.004912 | M62: -0.03834 | N62: 0.025722 | O62: 0.139253 | P62: -0.04215 | Q62: 0.075759 | R62: -0.0008 | S62: -0.05223 | T62: -0.02685 | U62: -0.10233 | V62: -0.10469 | W62: -0.10628 | X62: -0.12527 | Y62: -0.0794 | Z62: 0.031313 | AA62: -0.05293 | AB62: -0.1027 | AC62: -0.09904 | AD62: -0.04329 | AE62: -0.00079 | AF62: -0.01927 | AG62: -0.03121 | AH62: -0.21396 | AI62: 0.018106 | AJ62: 0.025474 | AK62: -0.06804 | AL62: -0.0748 | AM62: -0.1039 | AN62: -0.12221 | AO62: -0.07477 | AP62: -0.04059 | AQ62: -0.07443 | AR62: -0.22453 | AS62: -0.02073 | AT62: 0.06253 | AU62: -0.15101 | AV62: -0.0608 | AW62: -0.0357 | AX62: 1
B63: 4.348136 | C63: 3.348638 | D63: 2.408941 | E63: 5.351358 | F63: 6.323809 | G63: 6.498887 | H63: 7.656115 | I63: 6.335523 | J63: 6.771228 | K63: 6.268386 | L63: 7.033637 | M63: 7.071475 | N63: 6.614025 | O63: 2.699432 | P63: 3.585379 | Q63: 4.650366 | R63: 2.377934 | S63: 2.341553 | T63: 4.614693 | U63: 4.367207 | V63: 4.209673 | W63: 3.257338 | X63: 2.995288 | Y63: 0.940022 | Z63: 5.248997 | AA63: 4.993856 | AB63: 6.992916 | AC63: 6.152999 | AD63: 3.334434 | AE63: 2.206347 | AF63: 3.144117 | AG63: 4.620773 | AH63: 2.318871 | AI63: 5.819961 | AJ63: 5.46097 | AK63: 3.410198 | AL63: 2.259934 | AM63: 2.684595 | AN63: 3.352684 | AO63: 2.421389 | AP63: 3.6199 | AQ63: 5.095181 | AR63: 3.510625 | AS63: 3.222256 | AT63: 1.860852 | AU63: 0.682553 | AV63: 0.651404 | AW63: 0.892986 | AX63: 0.503585 | AY63: 196.5314
A65: Inverse of Correlation Matrix
B67: 1.Delay in delivering material to construction site | C67: 2.Monopoly of material by some suppliers | D67: 3.Prices fluctuation | E67: 4.Types of material availability at local market | F67: 5.Lack of consultant’s knowledge of available materials | G67: 6.Low productivity | H67: 7.Poor work execution | I67: 8.Shortage of laborers | J67: 9.Mistakes happens during construction phase | K67: 10.Unavailability of equipment | L67: 11.Lack of engineering experience | M67: 12.Construction cost underestimation | N67: 13.Poor site management | O67: 14.Delayed payment for completed work | P67: 15.Cash flow problem during construction | Q67: 16.High rate of interest | R67: 17.Contractor’s financial difficulties | S67: 18.Increase in salaries of skilled laborers | T67: 19.Change design | U67: 20.Errors and omission in design | V67: 21.Incomplete design drawings and specifications at tendering stage | W67: 22.Delay in preparation and approval of drawing | X67: 23.Inaccurate quantity take-off | Y67: 24.Long period from planning of project to construction | Z67: 25.Delays in issuing information to the contractor during construction stage | AA67: 26.No practical use of earned value management system | AB67: 27.Lack of cost planning/monitoring during pre and post contract stage | AC67: 28.Poor communication between client, consultant and contractor | AD67: 29.Insufficient coordination between local authority who is responsible about road projects and service authorities | AE67: 30.Delays in decisions making by the approval authorities | AF67: 31.Change schedule | AG67: 32.Stoppages because of work being rejected by consultant | AH67: 33.Lowest bid price | AI67: 34.Insufficient time for preparation of contract documents | AJ67: 35.Discrepancies in contract documents | AK67: 36.Underestimation of time for completion of project | AL67: 37.Extension of time with cost claims | AM67: 38.Scope and specification changes | AN67: 39.Changes in client requirements | AO67: 40.Frequency of variation orders and additional works | AP67: 41.Rework due to error in execution | AQ67: 42.Weather conditions | AR67: 43.Accidents during construction | AS67: 44.Delay in getting NOCs from different government authorities | AT67: Type of Organization | AU67: Respondents designation | AV67: Indicate the highest formal qualification | AW67: Location of organization | AX67: Relevant working experience
A68: 1.Delay in delivering material to construction site | B68: 5.647436 | C68: -2.67101 | D68: 1.477082 | E68: -1.75628 | F68: 0.720041 | G68: -1.16537 | H68: -0.41371 | I68: -0.31166 | J68: -1.63936 | K68: 0.52553 | L68: 0.240862 | M68: -1.31463 | N68: 1.694348 | O68: -0.17047 | P68: -1.00669 | Q68: 1.117167 | R68: 0.346376 | S68: -1.33589 | T68: 2.051066 | U68: 0.839972 | V68: -2.30245 | W68: 0.139233 | X68: 1.630809 | Y68: -0.18196 | Z68: -1.28393 | AA68: -0.60186 | AB68: 1.149882 | AC68: 0.064336 | AD68: 1.236751 | AE68: -0.62704 | AF68: 0.507504 | AG68: -0.50453 | AH68: -0.75937 | AI68: 1.459292 | AJ68: -1.97582 | AK68: 0.06686 | AL68: -0.52619 | AM68: 0.013363 | AN68: -0.01518 | AO68: -0.03696 | AP68: -0.48103 | AQ68: -0.51786 | AR68: 0.16314 | AS68: -0.04094 | AT68: 0.950375 | AU68: -0.7585 | AV68: 0.432416 | AW68: -0.01999 | AX68: 0.262861
A69: 2.Monopoly of material by some suppliers | B69: -2.67101 | C69: 5.899128 | D69: -1.0356 | E69: 0.093889 | F69: -1.36934 | G69: 1.409301 | H69: 0.282901 | I69: -1.91285 | J69: 1.352574 | K69: -0.17303 | L69: -0.94056 | M69: 3.095467 | N69: -1.04702 | O69: 1.59073 | P69: -0.60091 | Q69: -1.01967 | R69: -0.55797 | S69: 1.130508 | T69: -2.61518 | U69: -0.51872 | V69: 2.361373 | W69: -0.5996 | X69: -0.49339 | Y69: 0.256772 | Z69: 0.663733 | AA69: 1.124378 | AB69: -1.3285 | AC69: 0.503196 | AD69: -1.52593 | AE69: 2.158703 | AF69: -0.39774 | AG69: 0.225767 | AH69: 0.130892 | AI69: -0.10899 | AJ69: 2.054048 | AK69: -0.97483 | AL69: -0.09893 | AM69: 1.47633 | AN69: -0.99198 | AO69: -0.80754 | AP69: 0.181869 | AQ69: -0.0311 | AR69: -0.98345 | AS69: -0.75579 | AT69: -1.79622 | AU69: 0.476255 | AV69: -0.53644 | AW69: -0.23628 | AX69: 0.002804
A70: 3.Prices fluctuation | B70: 1.477082 | C70: -1.0356 | D70: 3.682232 | E70: -1.71427 | F70: 0.20592 | G70: -0.33351 | H70: -0.70129 | I70: 0.881674 | J70: -1.72162 | K70: 0.895146 | L70: -0.38904 | M70: -0.83438 | N70: -0.15421 | O70: 0.10347 | P70: -0.26655 | Q70: 0.380774 | R70: -0.29407 | S70: -0.44759 | T70: 0.641891 | U70: 0.125087 | V70: -0.93466 | W70: 0.131403 | X70: 0.833357 | Y70: -0.32367 | Z70: 0.52971 | AA70: -1.24702 | AB70: 1.095042 | AC70: 0.077556 | AD70: -0.02245 | AE70: 0.621948 | AF70: -0.33348 | AG70: 0.658458 | AH70: -0.62497 | AI70: -0.12854 | AJ70: 0.75711 | AK70: 0.275972 | AL70: -0.5019 | AM70: -0.59083 | AN70: 0.246151 | AO70: 0.519412 | AP70: -0.1676 | AQ70: -0.49851 | AR70: 0.579415 | AS70: -0.43139 | AT70: 0.250616 | AU70: -1.06997 | AV70: -0.16905 | AW70: -0.79878 | AX70: 0.261608
A71: 4.Types of material availability at local market | B71: -1.75628 | C71: 0.093889 | D71: -1.71427 | E71: 5.715597 | F71: -1.8185 | G71: -0.50317 | H71: -1.74368 | I71: -1.72523 | J71: 3.643406 | K71: -0.96095 | L71: -0.25759 | M71: 1.323138 | N71: 0.094894 | O71: 1.114553 | P71: -1.34562 | Q71: 0.399607 | R71: 1.121598 | S71: 0.011052 | T71: -0.42749 | U71: 0.712066 | V71: 0.241798 | W71: 0.325562 | X71: -1.14101 | Y71: -0.04348 | Z71: 0.412238 | AA71: 0.381628 | AB71: -0.67508 | AC71: -0.97044 | AD71: 0.742902 | AE71: -0.76691 | AF71: -0.39537 | AG71: 0.188135 | AH71: -0.49383 | AI71: 0.341102 | AJ71: 0.099448 | AK71: -1.09183 | AL71: 0.445062 | AM71: 0.309512 | AN71: 0.064072 | AO71: -0.33739 | AP71: 0.401603 | AQ71: -0.52014 | AR71: -0.65303 | AS71: 1.106821 | AT71: -0.36966 | AU71: 0.130188 | AV71: -0.28392 | AW71: -0.28419 | AX71: -0.31729
A72: 5.Lack of consultant’s knowledge of available materials | B72: 0.720041 | C72: -1.36934 | D72: 0.20592 | E72: -1.8185 | F72: 5.766082 | G72: -0.69744 | H72: 1.712937 | I72: 1.631987 | J72: -2.70322 | K72: 0.67808 | L72: 1.04383 | M72: -0.80378 | N72: -2.30218 | O72: -2.12624 | P72: 1.628767 | Q72: -0.18824 | R72: 0.326725 | S72: -0.89928 | T72: 0.941481 | U72: -0.17346 | V72: -1.43203 | W72: 0.214721 | X72: -0.29448 | Y72: 0.498635 | Z72: -0.93691 | AA72: -1.22075 | AB72: 1.014716 | AC72: -0.79189 | AD72: 0.704704 | AE72: 0.243813 | AF72: 2.06524 | AG72: -1.55656 | AH72: -0.83019 | AI72: 0.227065 | AJ72: -1.72519 | AK72: 1.538451 | AL72: -0.95426 | AM72: -0.29833 | AN72: -1.19592 | AO72: 1.828248 | AP72: -0.08951 | AQ72: -0.59064 | AR72: 0.989397 | AS72: -0.13378 | AT72: 1.035443 | AU72: 0.665108 | AV72: 0.498894 | AW72: 0.054297 | AX72: 0.835127
A73: 6.Low productivity | B73: -1.16537 | C73: 1.409301 | D73: -0.33351 | E73: -0.50317 | F73: -0.69744 | G73: 8.985356 | H73: -4.34322 | I73: -3.5193 | J73: -0.38764 | K73: 0.383197 | L73: -0.35554 | M73: 0.775473 | N73: -0.49994 | O73: 1.342058 | P73: 0.240716 | Q73: -0.86901 | R73: -0.86978 | S73: 0.27063 | T73: -0.89132 | U73: -0.63832 | V73: 1.27133 | W73: 0.129152 | X73: -0.29495 | Y73: 0.802811 | Z73: -0.00359 | AA73: 1.605502 | AB73: -1.94541 | AC73: 2.092233 | AD73: -2.61693 | AE73: 1.233791 | AF73: -0.75334 | AG73: 0.360004 | AH73: 1.399634 | AI73: -1.29327 | AJ73: 1.975446 | AK73: -0.74575 | AL73: -0.65139 | AM73: -0.25761 | AN73: 1.098501 | AO73: -1.24108 | AP73: 0.418348 | AQ73: 1.036602 | AR73: -0.21013 | AS73: 0.51481 | AT73: -1.42705 | AU73: -0.36933 | AV73: 0.381331 | AW73: 0.619021 | AX73: -0.63518
A74: 7.Poor work execution | B74: -0.41371 | C74: 0.282901 | D74: -0.70129 | E74: -1.74368 | F74: 1.712937 | G74: -4.34322 | H74: 9.815002 | I74: 2.974926 | J74: -3.53326 | K74: -0.89263 | L74: -0.63138 | M74: 1.33726 | N74: -1.59203 | O74: -2.81755 | P74: 2.729005 | Q74: 0.26272 | R74: -0.91794 | S74: 0.864901 | T74: -0.96683 | U74: 0.064079 | V74: 1.108265 | W74: -0.39093 | X74: 0.836058 | Y74: 0.33721 | Z74: -1.16199 | AA74: -1.12577 | AB74: 0.797739 | AC74: -0.4257 | AD74: 0.372693 | AE74: -0.74367 | AF74: 2.073979 | AG74: -2.3397 | AH74: -0.02895 | AI74: -0.55428 | AJ74: -0.62537 | AK74: 1.326819 | AL74: 0.205936 | AM74: -0.25939 | AN74: -2.42245 | AO74: 2.12043 | AP74: -1.33727 | AQ74: -0.58073 | AR74: 0.889806 | AS74: -0.70775 | AT74: -0.11575 | AU74: 0.536418 | AV74: 0.26072 | AW74: 0.577858 | AX74: 0.868215
A75: 8.Shortage of laborers | B75: -0.31166 | C75: -1.91285 | D75: 0.881674 | E75: -1.72523 | F75: 1.631987 | G75: -3.5193 | H75: 2.974926 | I75: 9.42749 | J75: -3.06174 | K75: -2.1964 | L75: -0.4656 | M75: -2.83949 | N75: -1.01301 | O75: -2.60896 | P75: 2.302824 | Q75: 1.564668 | R75: -0.84868 | S75: 0.017329 | T75: -0.53281 | U75: -1.00908 | V75: 1.365456 | W75: 0.091138 | X75: 1.167602 | Y75: 0.155935 | Z75: -0.8906 | AA75: -2.31248 | AB75: 2.455223 | AC75: -0.59138 | AD75: 0.731326 | AE75: -1.22791 | AF75: 0.687739 | AG75: -0.58751 | AH75: 0.42983 | AI75: -2.17214 | AJ75: 0.509295 | AK75: 2.76865 | AL75: -0.45676 | AM75: -1.79198 | AN75: 0.447539 | AO75: 1.795596 | AP75: -0.22095 | AQ75: -0.0353 | AR75: 0.352477 | AS75: -0.15798 | AT75: 1.175609 | AU75: 0.544724 | AV75: -0.15699 | AW75: 0.083305 | AX75: 0.146912
A76: 9.Mistakes happens during construction phase | B76: -1.63936 | C76: 1.352574 | D76: -1.72162 | E76: 3.643406 | F76: -2.70322 | G76: -0.38764 | H76: -3.53326 | I76: -3.06174 | J76: 11.68938 | K76: -2.43824 | L76: -0.58032 | M76: -0.27822 | N76: -0.1799 | O76: 2.635605 | P76: -3.02519 | Q76: -0.46159 | R76: 3.512277 | S76: 0.449685 | T76: -2.31911 | U76: 0.685597 | V76: 1.971696 | W76: -1.37624 | X76: -1.91398 | Y76: -1.07006 | Z76: 2.083658 | AA76: 0.912322 | AB76: -1.6296 | AC76: -1.85488 | AD76: -0.1926 | AE76: -0.03973 | AF76: -0.87244 | AG76: 0.31855 | AH76: 0.535254 | AI76: 1.017788 | AJ76: 0.13402 | AK76: -2.94903 | AL76: 0.802502 | AM76: 1.284074 | AN76: 1.327066 | AO76: -1.9145 | AP76: 1.086275 | AQ76: 1.097464 | AR76: -1.79606 | AS76: 2.061878 | AT76: 0.412083 | AU76: 1.215824 | AV76: -1.50885 | AW76: -0.5311 | AX76: -0.36411
A77: 10.Unavailability of equipment | B77: 0.52553 | C77: -0.17303 | D77: 0.895146 | E77: -0.96095 | F77: 0.67808 | G77: 0.383197 | H77: -0.89263 | I77: -2.1964 | J77: -2.43824 | K77: 7.081276 | L77: -0.37754 | M77: -2.69979 | N77: 1.528933 | O77: 0.073972 | P77: -0.41215 | Q77: -0.39607 | R77: -1.76276 | S77: -0.05795 | T77: 1.935416 | U77: -0.40454 | V77: -0.43721 | W77: 0.710437 | X77: -0.40885 | Y77: 0.815533 | Z77: 0.303768 | AA77: -0.00906 | AB77: -0.91631 | AC77: -0.91019 | AD77: 0.547003 | AE77: 1.21021 | AF77: 0.037556 | AG77: 0.355672 | AH77: -1.27279 | AI77: 1.063095 | AJ77: 0.093874 | AK77: 1.088695 | AL77: -0.44565 | AM77: 0.330836 | AN77: -0.7759 | AO77: -0.35762 | AP77: 0.051877 | AQ77: -1.22261 | AR77: 1.406534 | AS77: -1.4935 | AT77: 0.595652 | AU77: -1.05575 | AV77: -0.15831 | AW77: -0.04912 | AX77: -0.00144
A78: 11.Lack of engineering experience | B78: 0.240862 | C78: -0.94056 | D78: -0.38904 | E78: -0.25759 | F78: 1.04383 | G78: -0.35554 | H78: -0.63138 | I78: -0.4656 | J78: -0.58032 | K78: -0.37754 | L78: 6.864992 | M78: -1.22976 | N78: -2.16364 | O78: -0.92798 | P78: 0.289195 | Q78: -0.41682 | R78: 0.244643 | S78: -0.86035 | T78: 0.712622 | U78: 0.118274 | V78: -2.57599 | W78: 1.169481 | X78: 0.657137 | Y78: -0.50031 | Z78: -0.45574 | AA78: -0.21136 | AB78: 0.508585 | AC78: -0.76654 | AD78: -0.10885 | AE78: 0.016851 | AF78: 0.847491 | AG78: 0.681306 | AH78: -0.55669 | AI78: 1.053028 | AJ78: -1.71845 | AK78: -0.39116 | AL78: 0.050992 | AM78: 1.41047 | AN78: 0.483635 | AO78: 0.247053 | AP78: -0.96653 | AQ78: -0.30106 | AR78: -0.26615 | AS78: 0.760393 | AT78: 0.46567 | AU78: 0.847838 | AV78: -0.07286 | AW78: 0.154062 | AX78: 0.025512
A79: 12.Construction cost underestimation | B79: -1.31463 | C79: 3.095467 | D79: -0.83438 | E79: 1.323138 | F79: -0.80378 | G79: 0.775473 | H79: 1.33726 | I79: -2.83949 | J79: -0.27822 | K79: -2.69979 | L79: -1.22976 | M79: 10.76744 | N79: -2.58504 | O79: 1.720109 | P79: -0.04752 | Q79: -1.34463 | R79: 0.547632 | S79: 0.793047 | T79: -2.72284 | U79: 0.440179 | V79: 0.393219 | W79: -1.03041 | X79: 0.051212 | Y79: -0.1102 | Z79: 0.661964 | AA79: 0.696275 | AB79: -0.40007 | AC79: 1.126765 | AD79: -2.30284 | AE79: 1.832244 | AF79: -0.60697 | AG79: 0.748592 | AH79: -0.39424 | AI79: -0.48312 | AJ79: 1.785809 | AK79: -2.28482 | AL79: 0.979168 | AM79: -0.21403 | AN79: -1.47415 | AO79: 0.477591 | AP79: -0.28557 | AQ79: -0.89704 | AR79: -1.32709 | AS79: 0.178109 | AT79: -3.12516 | AU79: 0.29518 | AV79: 0.639152 | AW79: 0.304944 | AX79: -0.06003
... A116: Relevant working experience | B116: 0.262861 | C116: 0.002804 | D116: 0.261608 | E116: -0.31729 | F116: 0.835127 | G116: -0.63518 | H116: 0.868215 | I116: 0.146912 | J116: -0.36411 | K116: -0.00144 | L116: 0.025512 | M116: -0.06003 | N116: -0.27029 | O116: -1.19864 | P116: 0.743851 | Q116: -0.07021 | R116: 0.090355 | S116: -0.01847 | T116: -0.05637 | U116: 0.374427 | V116: -0.023 | W116: 0.338776 | X116: 0.064877 | Y116: -0.0031 | Z116: -0.36989 | AA116: -0.36146 | AB116: 0.219761 | AC116: 0.032299 | AD116: 0.191367 | AE116: 0.039357 | AF116: 0.741206 | AG116: -0.97279 | AH116: 0.382748 | AI116: -0.13526 | AJ116: -0.58131 | AK116: 0.407205 | AL116: -0.04743 | AM116: 0.254972 | AN116: -0.6695 | AO116: 0.399377 | AP116: -0.06536 | AQ116: -0.48027 | AR116: 0.811174 | AS116: 0.019793 | AT116: -0.07713 | AU116: 0.218084 | AV116: 0.084118 | AW116: -0.03352 | AX116: 1.826698
A118: Partial Correlation Matrix
B120: 1.Delay in delivering material to construction site | C120: 2.Monopoly of material by some suppliers | D120: 3.Prices fluctuation | E120: 4.Types of material availability at local market | F120: 5.Lack of consultant’s knowledge of available materials | G120: 6.Low productivity | H120: 7.Poor work execution | I120: 8.Shortage of laborers | J120: 9.Mistakes happens during construction phase | K120: 10.Unavailability of equipment | L120: 11.Lack of engineering experience | M120: 12.Construction cost underestimation | N120: 13.Poor site management | O120: 14.Delayed payment for completed work | P120: 15.Cash flow problem during construction | Q120: 16.High rate of interest | R120: 17.Contractor’s financial difficulties | S120: 18.Increase in salaries of skilled laborers | T120: 19.Change design | U120: 20.Errors and omission in design | V120: 21.Incomplete design drawings and specifications at tendering stage | W120: 22.Delay in preparation and approval of drawing | X120: 23.Inaccurate quantity take-off | Y120: 24.Long period from planning of project to construction | Z120: 25.Delays in issuing information to the contractor during construction stage | AA120: 26.No practical use of earned value management system | AB120: 27.Lack of cost planning/monitoring during pre and post contract stage | AC120: 28.Poor communication between client, consultant and contractor | AD120: 29.Insufficient coordination between local authority who is responsible about road projects and service authorities | AE120: 30.Delays in decisions making by the approval authorities | AF120: 31.Change schedule | AG120: 32.Stoppages because of work being rejected by consultant | AH120: 33.Lowest bid price | AI120: 34.Insufficient time for preparation of contract documents | AJ120: 35.Discrepancies in contract documents | AK120: 36.Underestimation of time for completion of project | AL120: 37.Extension of time with cost claims | AM120: 38.Scope and specification changes | AN120: 39.Changes in client requirements | AO120: 40.Frequency of variation orders and additional works | AP120: 41.Rework due to error in execution | AQ120: 42.Weather conditions | AR120: 43.Accidents during construction | AS120: 44.Delay in getting NOCs from different government authorities | AT120: Type of Organization | AU120: Respondents designation | AV120: Indicate the highest formal qualification | AW120: Location of organization | AX120: Relevant working experience
A121: 1.Delay in delivering material to construction site | B121: 1 | C121: 0.462761 | D121: -0.32391 | E121: 0.309128 | F121: -0.12618 | G121: 0.163595 | H121: 0.055568 | I121: 0.042712 | J121: 0.201769 | K121: -0.0831 | L121: -0.03868 | M121: 0.168586 | N121: -0.26334 | O121: 0.027151 | P121: 0.155106 | Q121: -0.23527 | R121: -0.06643 | S121: 0.303903 | T121: -0.33442 | U121: -0.15799 | V121: 0.326257 | W121: -0.02923 | X121: -0.331 | Y121: 0.05042 | Z121: 0.253004 | AA121: 0.111505 | AB121: -0.20052 | AC121: -0.01117 | AD121: -0.21877 | AE121: 0.137046 | AF121: -0.10324 | AG121: 0.088717 | AH121: 0.155263 | AI121: -0.21807 | AJ121: 0.292826 | AK121: -0.01201 | AL121: 0.122115 | AM121: -0.00263 | AN121: 0.002779 | AO121: 0.007891 | AP121: 0.111683 | AQ121: 0.079796 | AR121: -0.03151 | AS121: 0.008655 | AT121: -0.21116 | AU121: 0.19971 | AV121: -0.12687 | AW121: 0.005663 | AX121: -0.08184
...

Sheet Varimax
A1: Factor Matrix (rotated Varimax)
B3: Construction & Site Management Risk | C3: Design & Engineering Risk | D3: Financial Risk | E3: Scope Change & Client-Driven Risk | F3: External & Supply Chain Risk | G3: Economic & Market Conditions Risk (Weak factor) | H3: Regulatory & Administrative Risk | I3: Organizational Structure Risk (Weak factor) | J3: Planning & Scheduling Risk (Weak factor) | K3: Contractual & Estimation Risk (Weak factor) | L3: Qualification & Knowledge Risk (Weak factor) | N3: Commun | O3: Specific
B4: -0.50316 | C4: -0.08111 | D4: -0.07506 | E4: 0.022609 | F4: -0.54391 | G4: -0.1289 | H4: -0.06442 | I4: 0.075535 | J4: -0.05645 | K4: -0.06258 | L4: 0.265988 | N4: 0.666051 | O4: 0.333949
A5: 2.Monopoly of material by some suppliers | B5: -0.41288 | C5: 0.117371 | D5: -0.16713 | E5: -0.0988 | F5: -0.61786 | G5: -0.18374 | H5: 0.07491 | I5: 0.16891 | J5: 0.173656 | K5: -0.13134 | L5: 0.177381 | N5: 0.750471 | O5: 0.249529
A6: 3.Prices fluctuation | B6: -0.43584 | C6: 0.022585 | D6: -0.02703 | E6: 0.062301 | F6: -0.093 | G6: -0.62571 | H6: 0.186956 | I6: -0.03804 | J6: -0.10288 | K6: -0.02898 | L6: 0.080795 | N6: 0.649599 | O6: 0.350401
A7: 4.Types of material availability at local market | B7: -0.56568 | C7: 0.011497 | D7: -0.12429 | E7: -0.06408 | F7: -0.43016 | G7: -0.3293 | H7: 0.036395 | I7: -0.08709 | J7: -0.1645 | K7: -0.01806 | L7: 0.292366 | N7: 0.75493 | O7: 0.24507
A8: 5.Lack of consultant’s knowledge of available materials | B8: -0.46995 | C8: 0.40228 | D8: -0.0089 | E8: 0.173412 | F8: -0.3203 | G8: -0.16594 | H8: 0.019769 | I8: -0.01431 | J8: -0.24707 | K8: 0.051037 | L8: 0.118954 | N8: 0.621352 | O8: 0.378648
A9: 6.Low productivity | B9: -0.88026 | C9: 0.081796 | D9: 0.020737 | E9: 0.049099 | F9: -0.04497 | G9: 0.019716 | H9: -0.11684 | I9: -0.02084 | J9: -0.0059 | K9: 0.046577 | L9: -0.00235 | N9: 0.80309 | O9: 0.19691
